2019-07-04 10:21:51,141 INFO: FrontEnd startup [in C:\Users\Unstable\Documents\GitHub\pymvcapi\src\FrontEnd\app\__init__.py:48]
2019-07-04 10:21:54,161 ERROR: Exception on / [GET] [in c:\users\unstable\documents\github\pymvcapi\venv\lib\site-packages\flask\app.py:1780]
Traceback (most recent call last):
  File "c:\users\unstable\documents\github\pymvcapi\venv\lib\site-packages\sqlalchemy\util\_collections.py", line 1010, in __call__
    return self.registry[key]
KeyError: 11784

During handling of the above exception, another exception occurred:

Traceback (most recent call last):
  File "c:\users\unstable\documents\github\pymvcapi\venv\lib\site-packages\flask\app.py", line 2311, in wsgi_app
    response = self.full_dispatch_request()
  File "c:\users\unstable\documents\github\pymvcapi\venv\lib\site-packages\flask\app.py", line 1834, in full_dispatch_request
    rv = self.handle_user_exception(e)
  File "c:\users\unstable\documents\github\pymvcapi\venv\lib\site-packages\flask\app.py", line 1737, in handle_user_exception
    reraise(exc_type, exc_value, tb)
  File "c:\users\unstable\documents\github\pymvcapi\venv\lib\site-packages\flask\_compat.py", line 36, in reraise
    raise value
  File "c:\users\unstable\documents\github\pymvcapi\venv\lib\site-packages\flask\app.py", line 1830, in full_dispatch_request
    rv = self.preprocess_request()
  File "c:\users\unstable\documents\github\pymvcapi\venv\lib\site-packages\flask\app.py", line 2106, in preprocess_request
    rv = func()
  File "C:\Users\Unstable\Documents\GitHub\pymvcapi\src\FrontEnd\app\routes.py", line 12, in before_request
    if current_user.is_authenticated:
  File "c:\users\unstable\documents\github\pymvcapi\venv\lib\site-packages\werkzeug\local.py", line 348, in __getattr__
    return getattr(self._get_current_object(), name)
  File "c:\users\unstable\documents\github\pymvcapi\venv\lib\site-packages\werkzeug\local.py", line 307, in _get_current_object
    return self.__local()
  File "c:\users\unstable\documents\github\pymvcapi\venv\lib\site-packages\flask_login\utils.py", line 26, in <lambda>
    current_user = LocalProxy(lambda: _get_user())
  File "c:\users\unstable\documents\github\pymvcapi\venv\lib\site-packages\flask_login\utils.py", line 335, in _get_user
    current_app.login_manager._load_user()
  File "c:\users\unstable\documents\github\pymvcapi\venv\lib\site-packages\flask_login\login_manager.py", line 359, in _load_user
    return self.reload_user()
  File "c:\users\unstable\documents\github\pymvcapi\venv\lib\site-packages\flask_login\login_manager.py", line 321, in reload_user
    user = self.user_callback(user_id)
  File "C:\Users\Unstable\Documents\GitHub\pymvcapi\src\FrontEnd\app\models.py", line 15, in load_user
    return User.query.get(int(id))
  File "c:\users\unstable\documents\github\pymvcapi\venv\lib\site-packages\flask_sqlalchemy\__init__.py", line 519, in __get__
    return type.query_class(mapper, session=self.sa.session())
  File "c:\users\unstable\documents\github\pymvcapi\venv\lib\site-packages\sqlalchemy\orm\scoping.py", line 78, in __call__
    return self.registry()
  File "c:\users\unstable\documents\github\pymvcapi\venv\lib\site-packages\sqlalchemy\util\_collections.py", line 1012, in __call__
    return self.registry.setdefault(key, self.createfunc())
  File "c:\users\unstable\documents\github\pymvcapi\venv\lib\site-packages\sqlalchemy\orm\session.py", line 3214, in __call__
    return self.class_(**local_kw)
  File "c:\users\unstable\documents\github\pymvcapi\venv\lib\site-packages\flask_sqlalchemy\__init__.py", line 138, in __init__
    bind = options.pop('bind', None) or db.engine
  File "c:\users\unstable\documents\github\pymvcapi\venv\lib\site-packages\flask_sqlalchemy\__init__.py", line 937, in engine
    return self.get_engine()
  File "c:\users\unstable\documents\github\pymvcapi\venv\lib\site-packages\flask_sqlalchemy\__init__.py", line 956, in get_engine
    return connector.get_engine()
  File "c:\users\unstable\documents\github\pymvcapi\venv\lib\site-packages\flask_sqlalchemy\__init__.py", line 559, in get_engine
    sa_url = make_url(uri)
  File "c:\users\unstable\documents\github\pymvcapi\venv\lib\site-packages\sqlalchemy\engine\url.py", line 229, in make_url
    return _parse_rfc1738_args(name_or_url)
  File "c:\users\unstable\documents\github\pymvcapi\venv\lib\site-packages\sqlalchemy\engine\url.py", line 288, in _parse_rfc1738_args
    return URL(name, **components)
  File "c:\users\unstable\documents\github\pymvcapi\venv\lib\site-packages\sqlalchemy\engine\url.py", line 71, in __init__
    self.port = int(port)
ValueError: invalid literal for int() with base 10: '1433?Driver=ODBC+Driver+13+for+SQL+Server'
2019-07-04 10:22:24,860 INFO: FrontEnd startup [in C:\Users\Unstable\Documents\GitHub\pymvcapi\src\FrontEnd\app\__init__.py:48]
