2019-07-04 10:22:35,050 ERROR: Exception on /favicon.ico [GET] [in c:\users\unstable\documents\github\pymvcapi\venv\lib\site-packages\flask\app.py:1780]
Traceback (most recent call last):
  File "c:\users\unstable\documents\github\pymvcapi\venv\lib\site-packages\sqlalchemy\engine\base.py", line 2262, in _wrap_pool_connect
    return fn()
  File "c:\users\unstable\documents\github\pymvcapi\venv\lib\site-packages\sqlalchemy\pool\base.py", line 363, in connect
    return _ConnectionFairy._checkout(self)
  File "c:\users\unstable\documents\github\pymvcapi\venv\lib\site-packages\sqlalchemy\pool\base.py", line 760, in _checkout
    fairy = _ConnectionRecord.checkout(pool)
  File "c:\users\unstable\documents\github\pymvcapi\venv\lib\site-packages\sqlalchemy\pool\base.py", line 492, in checkout
    rec = pool._do_get()
  File "c:\users\unstable\documents\github\pymvcapi\venv\lib\site-packages\sqlalchemy\pool\impl.py", line 139, in _do_get
    self._dec_overflow()
  File "c:\users\unstable\documents\github\pymvcapi\venv\lib\site-packages\sqlalchemy\util\langhelpers.py", line 68, in __exit__
    compat.reraise(exc_type, exc_value, exc_tb)
  File "c:\users\unstable\documents\github\pymvcapi\venv\lib\site-packages\sqlalchemy\util\compat.py", line 154, in reraise
    raise value
  File "c:\users\unstable\documents\github\pymvcapi\venv\lib\site-packages\sqlalchemy\pool\impl.py", line 136, in _do_get
    return self._create_connection()
  File "c:\users\unstable\documents\github\pymvcapi\venv\lib\site-packages\sqlalchemy\pool\base.py", line 308, in _create_connection
    return _ConnectionRecord(self)
  File "c:\users\unstable\documents\github\pymvcapi\venv\lib\site-packages\sqlalchemy\pool\base.py", line 437, in __init__
    self.__connect(first_connect_check=True)
  File "c:\users\unstable\documents\github\pymvcapi\venv\lib\site-packages\sqlalchemy\pool\base.py", line 639, in __connect
    connection = pool._invoke_creator(self)
  File "c:\users\unstable\documents\github\pymvcapi\venv\lib\site-packages\sqlalchemy\engine\strategies.py", line 114, in connect
    return dialect.connect(*cargs, **cparams)
  File "c:\users\unstable\documents\github\pymvcapi\venv\lib\site-packages\sqlalchemy\engine\default.py", line 451, in connect
    return self.dbapi.connect(*cargs, **cparams)
pyodbc.InterfaceError: ('IM002', '[IM002] [Microsoft][ODBC Driver Manager] Data source name not found and no default driver specified (0) (SQLDriverConnect)')

The above exception was the direct cause of the following exception:

Traceback (most recent call last):
  File "c:\users\unstable\documents\github\pymvcapi\venv\lib\site-packages\flask\app.py", line 2311, in wsgi_app
    response = self.full_dispatch_request()
  File "c:\users\unstable\documents\github\pymvcapi\venv\lib\site-packages\flask\app.py", line 1834, in full_dispatch_request
    rv = self.handle_user_exception(e)
  File "c:\users\unstable\documents\github\pymvcapi\venv\lib\site-packages\flask\app.py", line 1737, in handle_user_exception
    reraise(exc_type, exc_value, tb)
  File "c:\users\unstable\documents\github\pymvcapi\venv\lib\site-packages\flask\_compat.py", line 36, in reraise
    raise value
  File "c:\users\unstable\documents\github\pymvcapi\venv\lib\site-packages\flask\app.py", line 1830, in full_dispatch_request
    rv = self.preprocess_request()
  File "c:\users\unstable\documents\github\pymvcapi\venv\lib\site-packages\flask\app.py", line 2106, in preprocess_request
    rv = func()
  File "C:\Users\Unstable\Documents\GitHub\pymvcapi\src\FrontEnd\app\routes.py", line 12, in before_request
    if current_user.is_authenticated:
  File "c:\users\unstable\documents\github\pymvcapi\venv\lib\site-packages\werkzeug\local.py", line 348, in __getattr__
    return getattr(self._get_current_object(), name)
  File "c:\users\unstable\documents\github\pymvcapi\venv\lib\site-packages\werkzeug\local.py", line 307, in _get_current_object
    return self.__local()
  File "c:\users\unstable\documents\github\pymvcapi\venv\lib\site-packages\flask_login\utils.py", line 26, in <lambda>
    current_user = LocalProxy(lambda: _get_user())
  File "c:\users\unstable\documents\github\pymvcapi\venv\lib\site-packages\flask_login\utils.py", line 335, in _get_user
    current_app.login_manager._load_user()
  File "c:\users\unstable\documents\github\pymvcapi\venv\lib\site-packages\flask_login\login_manager.py", line 359, in _load_user
    return self.reload_user()
  File "c:\users\unstable\documents\github\pymvcapi\venv\lib\site-packages\flask_login\login_manager.py", line 321, in reload_user
    user = self.user_callback(user_id)
  File "C:\Users\Unstable\Documents\GitHub\pymvcapi\src\FrontEnd\app\models.py", line 15, in load_user
    return User.query.get(int(id))
  File "c:\users\unstable\documents\github\pymvcapi\venv\lib\site-packages\sqlalchemy\orm\query.py", line 959, in get
    return self._get_impl(ident, loading.load_on_pk_identity)
  File "c:\users\unstable\documents\github\pymvcapi\venv\lib\site-packages\sqlalchemy\orm\query.py", line 1069, in _get_impl
    return db_load_fn(self, primary_key_identity)
  File "c:\users\unstable\documents\github\pymvcapi\venv\lib\site-packages\sqlalchemy\orm\loading.py", line 282, in load_on_pk_identity
    return q.one()
  File "c:\users\unstable\documents\github\pymvcapi\venv\lib\site-packages\sqlalchemy\orm\query.py", line 3282, in one
    ret = self.one_or_none()
  File "c:\users\unstable\documents\github\pymvcapi\venv\lib\site-packages\sqlalchemy\orm\query.py", line 3251, in one_or_none
    ret = list(self)
  File "c:\users\unstable\documents\github\pymvcapi\venv\lib\site-packages\sqlalchemy\orm\query.py", line 3324, in __iter__
    return self._execute_and_instances(context)
  File "c:\users\unstable\documents\github\pymvcapi\venv\lib\site-packages\sqlalchemy\orm\query.py", line 3346, in _execute_and_instances
    querycontext, self._connection_from_session, close_with_result=True
  File "c:\users\unstable\documents\github\pymvcapi\venv\lib\site-packages\sqlalchemy\orm\query.py", line 3361, in _get_bind_args
    mapper=self._bind_mapper(), clause=querycontext.statement, **kw
  File "c:\users\unstable\documents\github\pymvcapi\venv\lib\site-packages\sqlalchemy\orm\query.py", line 3339, in _connection_from_session
    conn = self.session.connection(**kw)
  File "c:\users\unstable\documents\github\pymvcapi\venv\lib\site-packages\sqlalchemy\orm\session.py", line 1124, in connection
    execution_options=execution_options,
  File "c:\users\unstable\documents\github\pymvcapi\venv\lib\site-packages\sqlalchemy\orm\session.py", line 1130, in _connection_for_bind
    engine, execution_options
  File "c:\users\unstable\documents\github\pymvcapi\venv\lib\site-packages\sqlalchemy\orm\session.py", line 431, in _connection_for_bind
    conn = bind._contextual_connect()
  File "c:\users\unstable\documents\github\pymvcapi\venv\lib\site-packages\sqlalchemy\engine\base.py", line 2226, in _contextual_connect
    self._wrap_pool_connect(self.pool.connect, None),
  File "c:\users\unstable\documents\github\pymvcapi\venv\lib\site-packages\sqlalchemy\engine\base.py", line 2266, in _wrap_pool_connect
    e, dialect, self
  File "c:\users\unstable\documents\github\pymvcapi\venv\lib\site-packages\sqlalchemy\engine\base.py", line 1536, in _handle_dbapi_exception_noconnection
    util.raise_from_cause(sqlalchemy_exception, exc_info)
  File "c:\users\unstable\documents\github\pymvcapi\venv\lib\site-packages\sqlalchemy\util\compat.py", line 399, in raise_from_cause
    reraise(type(exception), exception, tb=exc_tb, cause=cause)
  File "c:\users\unstable\documents\github\pymvcapi\venv\lib\site-packages\sqlalchemy\util\compat.py", line 153, in reraise
    raise value.with_traceback(tb)
  File "c:\users\unstable\documents\github\pymvcapi\venv\lib\site-packages\sqlalchemy\engine\base.py", line 2262, in _wrap_pool_connect
    return fn()
  File "c:\users\unstable\documents\github\pymvcapi\venv\lib\site-packages\sqlalchemy\pool\base.py", line 363, in connect
    return _ConnectionFairy._checkout(self)
  File "c:\users\unstable\documents\github\pymvcapi\venv\lib\site-packages\sqlalchemy\pool\base.py", line 760, in _checkout
    fairy = _ConnectionRecord.checkout(pool)
  File "c:\users\unstable\documents\github\pymvcapi\venv\lib\site-packages\sqlalchemy\pool\base.py", line 492, in checkout
    rec = pool._do_get()
  File "c:\users\unstable\documents\github\pymvcapi\venv\lib\site-packages\sqlalchemy\pool\impl.py", line 139, in _do_get
    self._dec_overflow()
  File "c:\users\unstable\documents\github\pymvcapi\venv\lib\site-packages\sqlalchemy\util\langhelpers.py", line 68, in __exit__
    compat.reraise(exc_type, exc_value, exc_tb)
  File "c:\users\unstable\documents\github\pymvcapi\venv\lib\site-packages\sqlalchemy\util\compat.py", line 154, in reraise
    raise value
  File "c:\users\unstable\documents\github\pymvcapi\venv\lib\site-packages\sqlalchemy\pool\impl.py", line 136, in _do_get
    return self._create_connection()
  File "c:\users\unstable\documents\github\pymvcapi\venv\lib\site-packages\sqlalchemy\pool\base.py", line 308, in _create_connection
    return _ConnectionRecord(self)
  File "c:\users\unstable\documents\github\pymvcapi\venv\lib\site-packages\sqlalchemy\pool\base.py", line 437, in __init__
    self.__connect(first_connect_check=True)
  File "c:\users\unstable\documents\github\pymvcapi\venv\lib\site-packages\sqlalchemy\pool\base.py", line 639, in __connect
    connection = pool._invoke_creator(self)
  File "c:\users\unstable\documents\github\pymvcapi\venv\lib\site-packages\sqlalchemy\engine\strategies.py", line 114, in connect
    return dialect.connect(*cargs, **cparams)
  File "c:\users\unstable\documents\github\pymvcapi\venv\lib\site-packages\sqlalchemy\engine\default.py", line 451, in connect
    return self.dbapi.connect(*cargs, **cparams)
sqlalchemy.exc.InterfaceError: (pyodbc.InterfaceError) ('IM002', '[IM002] [Microsoft][ODBC Driver Manager] Data source name not found and no default driver specified (0) (SQLDriverConnect)')
(Background on this error at: http://sqlalche.me/e/rvf5)
