2019-07-01 10:17:42,853 INFO: FrontEnd startup [in C:\Users\Unstable\Documents\GitHub\pymvcapi\src\FrontEnd\app\__init__.py:48]
2019-07-01 10:18:00,328 ERROR: Exception on /edit_profile [POST] [in c:\users\unstable\documents\github\pymvcapi\venv\lib\site-packages\flask\app.py:1780]
Traceback (most recent call last):
  File "c:\users\unstable\documents\github\pymvcapi\venv\lib\site-packages\sqlalchemy\engine\base.py", line 1244, in _execute_context
    cursor, statement, parameters, context
  File "c:\users\unstable\documents\github\pymvcapi\venv\lib\site-packages\sqlalchemy\engine\default.py", line 550, in do_execute
    cursor.execute(statement, parameters)
pyodbc.IntegrityError: ('23000', "[23000] [Microsoft][SQL Server Native Client 11.0][SQL Server]Cannot insert duplicate key row in object 'dbo.user' with unique index 'ix_user_username'. The duplicate key value is (daniel). (2601) (SQLExecDirectW); [23000] [Microsoft][SQL Server Native Client 11.0][SQL Server]The statement has been terminated. (3621)")

The above exception was the direct cause of the following exception:

Traceback (most recent call last):
  File "c:\users\unstable\documents\github\pymvcapi\venv\lib\site-packages\flask\app.py", line 2311, in wsgi_app
    response = self.full_dispatch_request()
  File "c:\users\unstable\documents\github\pymvcapi\venv\lib\site-packages\flask\app.py", line 1834, in full_dispatch_request
    rv = self.handle_user_exception(e)
  File "c:\users\unstable\documents\github\pymvcapi\venv\lib\site-packages\flask\app.py", line 1737, in handle_user_exception
    reraise(exc_type, exc_value, tb)
  File "c:\users\unstable\documents\github\pymvcapi\venv\lib\site-packages\flask\_compat.py", line 36, in reraise
    raise value
  File "c:\users\unstable\documents\github\pymvcapi\venv\lib\site-packages\flask\app.py", line 1832, in full_dispatch_request
    rv = self.dispatch_request()
  File "c:\users\unstable\documents\github\pymvcapi\venv\lib\site-packages\flask\app.py", line 1818, in dispatch_request
    return self.view_functions[rule.endpoint](**req.view_args)
  File "c:\users\unstable\documents\github\pymvcapi\venv\lib\site-packages\flask_login\utils.py", line 261, in decorated_view
    return func(*args, **kwargs)
  File "C:\Users\Unstable\Documents\GitHub\pymvcapi\src\FrontEnd\app\routes.py", line 87, in edit_profile
    db.session.commit()
  File "c:\users\unstable\documents\github\pymvcapi\venv\lib\site-packages\sqlalchemy\orm\scoping.py", line 162, in do
    return getattr(self.registry(), name)(*args, **kwargs)
  File "c:\users\unstable\documents\github\pymvcapi\venv\lib\site-packages\sqlalchemy\orm\session.py", line 1027, in commit
    self.transaction.commit()
  File "c:\users\unstable\documents\github\pymvcapi\venv\lib\site-packages\sqlalchemy\orm\session.py", line 494, in commit
    self._prepare_impl()
  File "c:\users\unstable\documents\github\pymvcapi\venv\lib\site-packages\sqlalchemy\orm\session.py", line 473, in _prepare_impl
    self.session.flush()
  File "c:\users\unstable\documents\github\pymvcapi\venv\lib\site-packages\sqlalchemy\orm\session.py", line 2459, in flush
    self._flush(objects)
  File "c:\users\unstable\documents\github\pymvcapi\venv\lib\site-packages\sqlalchemy\orm\session.py", line 2597, in _flush
    transaction.rollback(_capture_exception=True)
  File "c:\users\unstable\documents\github\pymvcapi\venv\lib\site-packages\sqlalchemy\util\langhelpers.py", line 68, in __exit__
    compat.reraise(exc_type, exc_value, exc_tb)
  File "c:\users\unstable\documents\github\pymvcapi\venv\lib\site-packages\sqlalchemy\util\compat.py", line 154, in reraise
    raise value
  File "c:\users\unstable\documents\github\pymvcapi\venv\lib\site-packages\sqlalchemy\orm\session.py", line 2557, in _flush
    flush_context.execute()
  File "c:\users\unstable\documents\github\pymvcapi\venv\lib\site-packages\sqlalchemy\orm\unitofwork.py", line 422, in execute
    rec.execute(self)
  File "c:\users\unstable\documents\github\pymvcapi\venv\lib\site-packages\sqlalchemy\orm\unitofwork.py", line 589, in execute
    uow,
  File "c:\users\unstable\documents\github\pymvcapi\venv\lib\site-packages\sqlalchemy\orm\persistence.py", line 236, in save_obj
    update,
  File "c:\users\unstable\documents\github\pymvcapi\venv\lib\site-packages\sqlalchemy\orm\persistence.py", line 996, in _emit_update_statements
    statement, multiparams
  File "c:\users\unstable\documents\github\pymvcapi\venv\lib\site-packages\sqlalchemy\engine\base.py", line 988, in execute
    return meth(self, multiparams, params)
  File "c:\users\unstable\documents\github\pymvcapi\venv\lib\site-packages\sqlalchemy\sql\elements.py", line 287, in _execute_on_connection
    return connection._execute_clauseelement(self, multiparams, params)
  File "c:\users\unstable\documents\github\pymvcapi\venv\lib\site-packages\sqlalchemy\engine\base.py", line 1107, in _execute_clauseelement
    distilled_params,
  File "c:\users\unstable\documents\github\pymvcapi\venv\lib\site-packages\sqlalchemy\engine\base.py", line 1248, in _execute_context
    e, statement, parameters, cursor, context
  File "c:\users\unstable\documents\github\pymvcapi\venv\lib\site-packages\sqlalchemy\engine\base.py", line 1466, in _handle_dbapi_exception
    util.raise_from_cause(sqlalchemy_exception, exc_info)
  File "c:\users\unstable\documents\github\pymvcapi\venv\lib\site-packages\sqlalchemy\util\compat.py", line 399, in raise_from_cause
    reraise(type(exception), exception, tb=exc_tb, cause=cause)
  File "c:\users\unstable\documents\github\pymvcapi\venv\lib\site-packages\sqlalchemy\util\compat.py", line 153, in reraise
    raise value.with_traceback(tb)
  File "c:\users\unstable\documents\github\pymvcapi\venv\lib\site-packages\sqlalchemy\engine\base.py", line 1244, in _execute_context
    cursor, statement, parameters, context
  File "c:\users\unstable\documents\github\pymvcapi\venv\lib\site-packages\sqlalchemy\engine\default.py", line 550, in do_execute
    cursor.execute(statement, parameters)
sqlalchemy.exc.IntegrityError: (pyodbc.IntegrityError) ('23000', "[23000] [Microsoft][SQL Server Native Client 11.0][SQL Server]Cannot insert duplicate key row in object 'dbo.user' with unique index 'ix_user_username'. The duplicate key value is (daniel). (2601) (SQLExecDirectW); [23000] [Microsoft][SQL Server Native Client 11.0][SQL Server]The statement has been terminated. (3621)")
[SQL: UPDATE [user] SET username=?, about_me=? WHERE [user].id = ?]
[parameters: ('daniel', '', 2)]
(Background on this error at: http://sqlalche.me/e/gkpj)
2019-07-01 10:22:14,033 INFO: FrontEnd startup [in C:\Users\Unstable\Documents\GitHub\pymvcapi\src\FrontEnd\app\__init__.py:48]
2019-07-01 11:08:09,327 INFO: FrontEnd startup [in C:\Users\Unstable\Documents\GitHub\pymvcapi\src\FrontEnd\app\__init__.py:48]
2019-07-01 11:13:18,646 INFO: FrontEnd startup [in C:\Users\Unstable\Documents\GitHub\pymvcapi\src\FrontEnd\app\__init__.py:48]
2019-07-01 11:36:14,115 INFO: FrontEnd startup [in C:\Users\Unstable\Documents\GitHub\pymvcapi\src\FrontEnd\app\__init__.py:48]
2019-07-01 11:38:40,607 INFO: FrontEnd startup [in C:\Users\Unstable\Documents\GitHub\pymvcapi\src\FrontEnd\app\__init__.py:48]
2019-07-01 11:42:39,612 INFO: FrontEnd startup [in C:\Users\Unstable\Documents\GitHub\pymvcapi\src\FrontEnd\app\__init__.py:48]
2019-07-01 11:42:44,002 INFO: FrontEnd startup [in C:\Users\Unstable\Documents\GitHub\pymvcapi\src\FrontEnd\app\__init__.py:48]
2019-07-01 11:44:33,116 INFO: FrontEnd startup [in C:\Users\Unstable\Documents\GitHub\pymvcapi\src\FrontEnd\app\__init__.py:48]
2019-07-01 11:45:27,045 INFO: FrontEnd startup [in C:\Users\Unstable\Documents\GitHub\pymvcapi\src\FrontEnd\app\__init__.py:48]
2019-07-01 11:45:55,013 INFO: FrontEnd startup [in C:\Users\Unstable\Documents\GitHub\pymvcapi\src\FrontEnd\app\__init__.py:48]
2019-07-01 11:46:53,489 INFO: FrontEnd startup [in C:\Users\Unstable\Documents\GitHub\pymvcapi\src\FrontEnd\app\__init__.py:48]
2019-07-01 11:47:02,935 INFO: FrontEnd startup [in C:\Users\Unstable\Documents\GitHub\pymvcapi\src\FrontEnd\app\__init__.py:48]
2019-07-01 11:49:16,189 INFO: FrontEnd startup [in C:\Users\Unstable\Documents\GitHub\pymvcapi\src\FrontEnd\app\__init__.py:48]
2019-07-04 10:12:29,464 INFO: FrontEnd startup [in C:\Users\Unstable\Documents\GitHub\pymvcapi\src\FrontEnd\app\__init__.py:48]
2019-07-04 10:18:26,211 INFO: FrontEnd startup [in C:\Users\Unstable\Documents\GitHub\pymvcapi\src\FrontEnd\app\__init__.py:48]
